Workbook

Sheet FR_Définitions
B2: Registre des activités de traitement
B4: Identification du traitement
B5: ID | C5: Numéro unique d'identification du traitement
B6: Etablissement(s) | C6: Si l'organisme à plusieurs établissements, indique le ou les établissements concernés par ce traitement
B7: Nom du traitement | C7: Le nom du traitement doit être suffisamment explicite pour que l'on comprenne de manière macro ce que fait le traitement
B8: Date d'identification du traitement | C8: Date à laquelle le traitement a été créé dans le registre
B9: Date de mise à jour | C9: Date à laquelle les informations sur le traitement ont été mises à jour pour la dernière fois (raccourci clavier CTRL ; )
B10: Historique de modifications | C10: Liste de l'ensemble des modifications qui ont été réalisées dans le registre sur le traitement, afin d'assurer une traçabilité des actions
B11: Data Protection Officer | C11: Nom et coordonnées de la personne ayant le rôle de DPO pour le traitement
B12: Responsable de traitement | C12: Fonction de la personne ayant le rôle de responsable de traitement, c'est-à-dire qui détermine les finalités et les moyens du traitement. Il est donc souvent un membre de la Direction Générale de l'entreprise
B13: Représentant de l'entité responsable de la mise en œuvre du traitement | C13: Fonction du représentant de l'entité ou du service qui est en charge de mettre en œuvre le traitement. Par exemple, le représentant de l'entité responsable du traitement des CV des candidats est le responsable de l'équipe recrutement
B14: Responsable(s) conjoint(s) du traitement | C14: Fonctions des personnes qui déterminent conjointement les finalités et les moyens du traitement
B15: Finalité principale | C15: Objectif final spécifique, explicite et légitime pour lequel le traitement a lieu
B16: Sous-finalités | C16: Les sous-finalités doivent être rattachées à la finalité principale du traitement
B18: Données personnelles traitées
B19: Catégories de personnes concernées par le traitement | C19: Exemples : employés, prestataires, clients, partenaires…
B20: Données d'identification | C20: Exemples : nom, prénom, adresse postale, numéro de téléphone, adresse e-mail, photos, vidéos…
B21: Données de connexion | C21: Exemples : adresse IP, logs, cookies, historique de navigation…
B22: Données de localisation | C22: Exemples : positionnement GPS, GSM…
B23: Données sur le comportement et la vie personnelle | C23: Exemples : situation familiale, habitudes de vie, habitudes de consommation…
B24: Données économiques et financières | C24: Exemples : revenus, situation financière, situation fiscale, numéro de carte bancaire, RIB…
B25: Données professionnelles | C25: Exemples : nom de l'employeur, statut dans l'entreprise, contrat de travail…
B26: Catégories particulières de données | C26: Exemples : données sur l'origine raciale ou ethnique, les opinions politiques, les convictions religieuses ou philosophiques ou l'appartenance syndicale, données génétiques, données biométriques, données concernant la santé, la vie sexuelle, l'orientation sexuelle, données relatives aux condamnations pénales et aux infractions...
B28: Description du traitement
B29: Canaux de collecte des données | C29: Moyens par lesquels les données sont récupérées / collectées pour le traitement. Par exemple : mail, formulaire papier, caméras…
B30: Licéité du traitement | C30: Le traitement n'est licite que si la personne concernée a donné son consentement au traitement de ses données, si le traitement est nécessaire à l'exécution d'un contrat auquel la personne concernée est partie ou si le traitement est nécessaire au respect d'une obligation légale
B31: Recours au traitement automatisé (y compris profilage) | C31: Recours à un traitement non basé sur une intervention ou analyse humaine (y compris toute forme de traitement automatisé consistant à utiliser les données à caractère personnel pour évaluer ou prédire des éléments concernant la santé, la situation économique, les préférences personnelles, le comportement, [...] les déplacements d'une personne physique)
B32: Applications support du traitement | C32: Liste des applications ou logiciels qui sont utilisés dans le but de réaliser le traitement. Attention, une même application peut être considérée comme support de plusieurs traitements
B33: Dispositions existantes pour assurer la sécurité des données | C33: Liste des dispositifs en place pour assurer la sécurité des données du traitement. Il est possible ici de faire référence à des documents tels que le Dossier d'Architecture Technique, le PIA (Privacy Impact Assessment) ou toute autre documentation présentant les mesures de sécurité "standard" existantes dans l'entreprise
B34: Durée d'archivage courant | C34: Durée de conservation pour les archives dites courantes. Les archives courantes sont réservées à l'utilisation courante des données par les services responsables de la mise en œuvre du traitement
B35: Durée d'archivage définitif | C35: Durée de conservation des archives dites définitives. Les archives définitives sont réservées aux archives présentant un intérêt historique, statistique ou scientifique
B36: Catégories de destinataires | C36: Toute personne, service, entreprise filiale ou tiers ayant un accès aux données à caractère personnel du traitement
B37: Raisons du transfert vers les catégories de destinataires | C37: Intérêts des destinataires à recevoir les données à caractère personnel transférées
B38: Transferts hors UE | C38: Communications de données à caractère personnel qui font ou sont destinées à faire l'objet d'un traitement en dehors des Etats membres de l'Union Européenne
B39: Pays destinataires | C39: Pays dans lesquels sont basés les catégories de destinataires à qui les données sont communiquées
C43: Liste des données sensibles
C44: Pas de donnée sensible
C45: Origine raciale ou ethnique
C46: Opinions politiques
C47: Religieuses ou philosophiques
...

Sheet LookUp_Definition
A1: UIID | B1: Type Definition | C1: Definition Libelle | D1: Scope Client (iid du client)
A2: 1 | B2: Sensibilité | C2: Tres sensible | D2: 1
A3: 2 | B3: Sensibilité | C3: oeu sensible | D3: 1
A4: 3 | B4: Sensibilité | C4: Bof sensible | D4: 1
A5: 4 | B5: Sensibilité | C5: Extreme sensible | D5: 1
A6: 5 | B6: Sensibilité | C6: Aucune importance | D6: 1
A7: 6 | B7: DureeRetention | C7: 1 an | D7: 1
A8: 7 | B8: DureeRetention | C8: 2 ans | D8: -1
A9: 8 | B9: DureeRetention | C9: A vie | D9: 1
A10: 9 | B10: Sensibilité | C10: Tres sensible | D10: 2
A11: 10 | B11: Sensibilité | C11: oeu sensible | D11: 2
A12: 11 | B12: Sensibilité | C12: Bof sensible | D12: 2
A13: 12 | B13: Sensibilité | C13: Extreme sensible | D13: 2
... A17: 16 | B17: DureeRetention | C17: A vie | D17: 2

Sheet Registre de traitement
B1: Grille de collecte / Registre des activités de traitement - Organisme : Association LA BRETECHE
AN4: Analyse de conformité
B5: Identification du traitement | N5: Données personnelles traitées | X5: Description du traitement | AO5: Finalité | AQ5: Minimisation des DCP | AS5: Conservation des DCP | AU5: Sécurité des DCP | AW5: Consentement | AY5: Informations | BA5: Exercice des droits | BC5: Sous-traitance | BE5: Transfert hors UE | BG5: Registe et preuve | BL5: Critères PIA
B6: ID | C6: Etablissement(s) | D6: Données concernées | E6: Nom du traitement | F6: Date d'identification du traitement | G6: Date de mise à jour | H6: Historique des modifications | I6: Data Protection Officer | J6: Responsable de traitement | K6: Gestionnaire de la mise en œuvre du traitement | L6: Finalité principale | M6: Sous-finalités | N6: Catégories de personnes concernées par le traitement | O6: Données d'identification | P6: Données de connexion | Q6: Données de localisation | R6: Données sur le comportement et la vie personnelle | S6: Données économiques et financières | T6: Données professionnelles | U6: Catégories particulières de données (NIR, santé par exemple) | V6: Sensibilité | W6: Etude d'impact (PIA) | X6: Canaux de collecte des données | Y6: Licéité du traitement | Z6: Recours au traitements automatisés (y compris profilage) ? (Oui / Non) | AA6: Emplacement physique du traitement | AB6: Dispositions existantes pour assurer la sécurité des données | AC6: Emplacement numérique du traitement | AD6: Dispositions existantes pour assurer la sécurité des données | AE6: Hébergement | AF6: Durée de conservation | AG6: Archivage ? (Oui / Non) | AH6: Durée d'archivage | AI6: Catégories de destinataires | AJ6: Raisons du transfert vers les catégories de destinataires | AK6: Transferts hors UE (Oui / Non) | AL6: Pays destinataires | AM6: Commentaires | AN6: Impact du traitement | AO6: Détournement de finalité | AP6: Score | AQ6: Collecte de DCP inapprorpiées | AR6: Score2 | AS6: Conservation excessive de DCP | AT6: Score3 | AU6: Sécurisation insuffisante des DCP | AV6: Score4 | AW6: Vices du consentement | AX6: Score5 | AY6: Manque de transparence | AZ6: Score6 | BA6: Incapacité à permettre l'exercice des droits | BB6: Score7 | BC6: Transfert auprès d'un tiers mal encadré | BD6: Score8 | BE6: Transfert hors UE abusif | BF6: score9 | BG6: Défaut de preuve | BH6: Score10 | BI6: Score global | BJ6: Commentaires analyse | BK6: Exposition du traitement | BL6: évaluation / scoring | BM6: décision automatique | BN6: surveillance systématique | BO6: collecte de données sensibles | BP6: collecte de données personnelles à large échelle | BQ6: croisement de données | BR6: personnes vulnérables | BS6: usage innovant | BT6: exclusion du bénéfice d’un droit/contrat
B7: 1 | C7: DIME L'espoir ESAT LA Simonière ESAT Les espoirs Résidence du parc des bois Résidence La Combe SAVA Itinéraire Bis | D7: Demandeurs Familles et proches des demandeurs | E7: Pré inscription | F7: 44277 | G7: 25/06/2024 13/08/2024 23/08/2024 02/09/2024 19/12/2024 24/06/2025 15/07/2025 19/08/2025 | H7: Ajout des informations papiers de la Résidence du parc des bois Pour le SAVS It bis, plus de stockage papier Pour le DIME la Bretèche, ajout de donnée n° IEN, plus de papier Pour le SAVS Tinténiac, ajout info données sensibles Pour l'ESAT Les espoirs, ajout données CV Suppression données papier pour la résidence du parc des bois et ajout de ViaTrajectoire Ajout commentaire pour SAVS Mordelles (15/07/25) Modif données (19/08/2025) | I7: Groupe CREATIVE | J7: Directeur de l'organisme | K7: Chefs de service et directeurs & psychologue | L7: Collecter les informations personnelles permettant d’inscrire les demandeurs sur liste d’attente. | M7: Evaluer les besoins en accompagnement afin de déterminer si les capacité d'accueil sont en adéquation avec les besoins pour donner un avis sur la demande d'admission | N7: Demandeur, Proche des demandeurs, Familles et partenaires | O7: Nom d’usage Nom de naissance Prénom(s) Date de naissance, N° MSA/CAF, adresse, téléphone, email, n° dossier MDPH N° IEN (pour les jeunes scolarisés) | R7: Situation familiale Nombre d’enfant(s) Présence d’un aidant, prestation en place (SSIAD, ADMR…) Mesure de protection juridique, Objet de la demande, Permis de conduire et type (ESAT) | S7: Financements, aides, allocation et prestation de compensation | T7: CV et lettre de motivation pour les candidatures | U7: NIR Dossier médical sous pli (nomalement sauf pour les ESAT) Suivi médical en cours, traitement médicamenteux, médecin traitant, psychiatre, CMP, psychologue (Pas de données médicales au SAVS) ESAT Les espoirs - Pas de données médicales | V7: NIR (N° SS) + Concernant le santé | W7: Données sensibles (Art 9) ou données relatives aux condamnations pénales ou aux infractions (Art 10) | X7: Par le demandeur (usagers / famille / proches des usagers) par mail ou courrier ViaTrajectoire | Y7: Fondé sur le consentement préalable de la personne physique, | Z7: Non | AA7: Bureau de la personne chargée de l'accompagnement sociale à l'ESAT la simmnière SO pour SAVS Tinténiac Bureau du Chef du service social à l'ESAT Les Espoirs | AB7: Dans un classeur dans une armoire du bureau fermé à clé de la personne chargée de l'accompagnement sociale à l'ESAT la simonière Dans une armoire fermée à clé du bureau fermé à clé à l'ESAT Les Espoirs | AC7: Mediateam Messagerie Serveur de fichier ViaTrajectoire | AD7: User + MDP | AE7: Berger Levrault Microsoft AJP GCS SARA | AF7: Supprimer | AG7: Oui | AH7: Editeur | AI7: Interne : Directrice, chefs de service, secrétaire, coordinatrice, Service social, comission d'admission, chargé d'accompagnement, Psychologue Externe :Conseil départemental (MDPH, CLIC) | AJ7: SO | AK7: Non | AL7: SO | AM7: Résidence La Combe : Tout est dans mediateam ESAT Les Espoirs : Projet de passage 100% sur Mediateam SAVS Mordelles - Depuis le 1er appel, tout est sur Mediateam | AN7: 1 | AO7: 0 | AP7: =$AN7*AO7 -> 0 | AQ7: 0 | AR7: =$AN7*AQ7 -> 0 | AS7: 0 | AT7: =$AN7*AS7 -> 0 | AU7: 0 | AV7: =$AN7*AU7 -> 0 | AW7: 0 | AX7: =$AN7*AW7 -> 0 | AY7: 0 | AZ7: =$AN7*AY7 -> 0 | BA7: 0 | BB7: =$AN7*BA7 -> 0 | BC7: 0 | BD7: =$AN7*BC7 -> 0 | BE7: 0 | BF7: =$AN7*BE7 -> 0 | BG7: 0 | BH7: =$AN7*BG7 -> 0 | BI7: =AP7:AP7+AR7:AR7+AT7:AT7+AV7:AV7+AX7:AX7+AZ7:AZ7+BB7:BB7+BD7:BD7+BF7:BF7+BH7:BH7 -> 0 | BJ7: Se référer au document word de préconisation | BK7: 0 | BO7: X | BR7: X
B8: 2 | C8: DIME Rennes | D8: Demandeurs Familles et proches des demandeurs | E8: Pré inscription | F8: 44277 | G8: 45855 | H8: Séparation de ce traitement pour le DIME rennes | I8: Groupe CREATIVE | J8: Directeur de l'organisme | K8: Secrétaire de direction, chefs de service | L8: Collecter les informations personnelles permettant d’inscrire les demandeurs sur liste d’attente. | M8: Evaluer les besoins en accompagnement afin de déterminer si les capacité d'accueil sont en adéquation avec les besoins pour donner un avis sur la demande d'admission | N8: Demandeur, Proche des demandeurs, Familles et partenaires | O8: Nom d’usage Nom de naissance Prénom(s) Date de naissance, adresse, téléphone, email, n° dossier MDPH | P8: Accès à ViaTrajectoire | R8: Situation familiale Présence d’un aidant, prestation en place (SSIAD, ADMR…) Mesure de protection juridique, Objet de la demande | U8: Diagnostics (Suivi médical en cours, bilan médicaux), suivi extérieur existant | V8: Concernant le santé | W8: Données sensibles (Art 9) ou données relatives aux condamnations pénales ou aux infractions (Art 10) | X8: Par le demandeur (usagers / famille / proches des usagers) par mail ou courrier ViaTrajectoire | Y8: Fondé sur le consentement préalable de la personne physique, | Z8: Non | AA8: Bureau du secrétariat | AB8: Classeur dans un meuble du Bureau du secrétariat fermé à clé | AC8: Viatrajectoire Fichier excel sur le serveur (dossier secrétariat) | AD8: User + MDP | AE8: Etat AJP | AF8: 5 ans | AG8: Oui | AH8: Editeur | AI8: Interne : Chefs de service, secrétaire Externe :MDPH | AJ8: SO | AK8: Non | AL8: SO | AN8: 1 | AO8: 0 | AP8: =$AN8*AO8 -> 0 | AQ8: 0 | AR8: =$AN8*AQ8 -> 0 | AS8: 0 | AT8: =$AN8*AS8 -> 0 | AU8: 0 | AV8: =$AN8*AU8 -> 0 | AW8: 0 | AX8: =$AN8*AW8 -> 0 | AY8: 0 | AZ8: =$AN8*AY8 -> 0 | BA8: 0 | BB8: =$AN8*BA8 -> 0 | BC8: 0 | BD8: =$AN8*BC8 -> 0 | BE8: 0 | BF8: =$AN8*BE8 -> 0 | BG8: 0 | BH8: =$AN8*BG8 -> 0 | BI8: =AP8:AP8+AR8:AR8+AT8:AT8+AV8:AV8+AX8:AX8+AZ8:AZ8+BB8:BB8+BD8:BD8+BF8:BF8+BH8:BH8 -> 0 | BJ8: Se référer au document word de préconisation | BK8: 0 | BO8: X | BR8: X
B9: 3 | C9: DIME La Bretèche | D9: Demandeurs Familles et proches des demandeurs | E9: Pré inscription | F9: 44277 | G9: 45855 | H9: Séparation de ce traitement pour le DIME La Bretèche | I9: Groupe CREATIVE | J9: Directeur de l'organisme | K9: Secrétaire de direction, chefs de service | L9: Collecter les informations personnelles permettant d’inscrire les demandeurs sur liste d’attente. | M9: Evaluer les besoins en accompagnement afin de déterminer si les capacité d'accueil sont en adéquation avec les besoins pour donner un avis sur la demande d'admission | N9: Demandeur, Proche des demandeurs, Familles et partenaires | O9: Nom d’usage Nom de naissance Prénom(s) Date de naissance, adresse, téléphone, email, n° dossier MDPH | P9: Accès à ViaTrajectoire | R9: Situation familiale Présence d’un aidant, prestation en place (SSIAD, ADMR…) Mesure de protection juridique, Objet de la demande | U9: Diagnostics (Suivi médical en cours, bilan médicaux), suivi extérieur existant | V9: Concernant le santé | W9: Données sensibles (Art 9) ou données relatives aux condamnations pénales ou aux infractions (Art 10) | X9: Par le demandeur (usagers / famille / proches des usagers) par mail ou courrier ViaTrajectoire | Y9: Fondé sur le consentement préalable de la personne physique, | Z9: Non | AA9: SO | AB9: SO | AC9: Mail Via Trajectoire Mediateam | AD9: User + MDP | AE9: Microsoft Etat Berger Levrault | AF9: 5 ans | AG9: Oui | AH9: Editeur | AI9: Interne : Chefs de service, secrétaire Externe :MDPH | AJ9: SO | AK9: Non | AL9: SO | AN9: 1 | AO9: 0 | AP9: =$AN9*AO9 -> 0 | AQ9: 0 | AR9: =$AN9*AQ9 -> 0 | AS9: 0 | AT9: =$AN9*AS9 -> 0 | AU9: 0 | AV9: =$AN9*AU9 -> 0 | AW9: 0 | AX9: =$AN9*AW9 -> 0 | AY9: 0 | AZ9: =$AN9*AY9 -> 0 | BA9: 0 | BB9: =$AN9*BA9 -> 0 | BC9: 0 | BD9: =$AN9*BC9 -> 0 | BE9: 0 | BF9: =$AN9*BE9 -> 0 | BG9: 0 | BH9: =$AN9*BG9 -> 0 | BI9: =AP9:AP9+AR9:AR9+AT9:AT9+AV9:AV9+AX9:AX9+AZ9:AZ9+BB9:BB9+BD9:BD9+BF9:BF9+BH9:BH9 -> 0 | BJ9: Se référer au document word de préconisation | BK9: 0 | BO9: X | BR9: X
B10: 4 | C10: SAVS Tinténiac | D10: Demandeurs Familles et proches des demandeurs | E10: Pré inscription | F10: 45866 | I10: Groupe CREATIVE | J10: Directeur de l'organisme | K10: Secrétaire de direction | L10: Collecter les informations personnelles permettant d’inscrire les demandeurs sur liste d’attente. | M10: Evaluer les besoins en accompagnement afin de déterminer si les capacité d'accueil sont en adéquation avec les besoins pour donner un avis sur la demande d'admission | N10: Demandeur, Proche des demandeurs, Familles et partenaires | O10: Nom d’usage Nom de naissance Prénom(s) Date de naissance, adresse, téléphone, email, n° dossier MDPH | P10: Nom d’usage Nom de naissance Prénom(s) Date de naissance, , adresse, téléphone, email, n° dossier MDPH | U10: Orientation MDPH | V10: NIR (présent la notification MDPH) | W10: Données sensibles (Art 9) ou données relatives aux condamnations pénales ou aux infractions (Art 10) | X10: Par le demandeur (usagers / famille / proches des usagers) par mail ou courrier ViaTrajectoire | Y10: Fondé sur le consentement préalable de la personne physique, | Z10: Non | AA10: SO | AB10: SO | AC10: Mediateam | AD10: User + MDP | AE10: Berger Levrault | AF10: Supprimer | AG10: Oui | AH10: Editeur | AI10: Interne : Salarié Externe :Conseil départemental (MDPH, CLIC) | AJ10: SO | AK10: Non | AL10: SO | AN10: 1 | AO10: 0 | AP10: =$AN10*AO10 -> 0 | AQ10: 0 | AR10: =$AN10*AQ10 -> 0 | AS10: 0 | AT10: =$AN10*AS10 -> 0 | AU10: 0 | AV10: =$AN10*AU10 -> 0 | AW10: 0 | AX10: =$AN10*AW10 -> 0 | AY10: 0 | AZ10: =$AN10*AY10 -> 0 | BA10: 0 | BB10: =$AN10*BA10 -> 0 | BC10: 0 | BD10: =$AN10*BC10 -> 0 | BE10: 0 | BF10: =$AN10*BE10 -> 0 | BG10: 0 | BH10: =$AN10*BG10 -> 0 | BI10: =AP10:AP10+AR10:AR10+AT10:AT10+AV10:AV10+AX10:AX10+AZ10:AZ10+BB10:BB10+BD10:BD10+BF10:BF10+BH10:BH10 -> 0 | BJ10: Se référer au document word de préconisation | BK10: 0 | BO10: X | BR10: X
B11: 5 | C11: DIME La Bretèche | D11: Usagers Familles et proches des usagers | E11: Admission | F11: 44277 | G11: 45527 | H11: Ajout de données n° IEN, parcours de scolarité du jeune, ancien bilan de parcours (PPA, …), vaccinations, stockage en plus bureau des Assistantes sociales | I11: Groupe CREATIVE | J11: Directeur de l'organisme | K11: Chefs de service et directeurs | L11: Collecter les informations personnelles permettant d’enregistrer administrativement le nouvel usager | M11: - Gestion de l'admission - Etat des présences - Réalisation d'états statistiques ou de listes pour répondre à des besoins de gestion administrative - Gestion des élections des représentants CVS - Gestion des enquêtes (ANAP - EHPA...) - Rapport d'activité - Gestion des mutuelles - Gestion des contacts en cas d'urgence et de la personne de confiance - Gestion décès - Gestion de la facturation des usagers - Gestion du courrier - Gestion du linge - Gestion des repas - Gestion du droit à l'image | N11: Usagers Familles et proches des usagers | O11: Nom d’usage Nom de naissance Prénom(s) Date de naissance, lieu, ancienne adresse N° Sécurité sociale N° CAF/MSA, adresse, téléphone, photographie noms, prénoms, coordonnées téléphoniques et adresses email des intervenants nom et les coordonnées téléphoniques de la personne à contacter en cas d’urgence N° IEN | R11: - Situation familiale - Nombre d’enfant(s) - Lieu de résidence lors de l’enfance - Nombre de frères et sœurs - Origine et profession des parents - Provenance - Mesure de protection juridique - Goûts et loisirs | S11: - aides financieres - demande de prélevement + RIB | T11: Parcours de scolarité du jeune, ancien bilan de parcours (PPA, …) | U11: Carte d’invalidite copie de l’attestation de Sécurité sociale copie de l’extrait de jugement s’il existe une mesure de protection juridique copie de la dernière ordonnance antécédents Copie des vaccinations | V11: NIR (N° SS) Donnée de santé | W11: Données sensibles (Art 9) ou données relatives aux condamnations pénales ou aux infractions (Art 10) | X11: usager / famille / proches des usagers / organisme de protection juridique | Y11: Fondé sur l’exécution d’un contrat avec la personne physique concernée, | Z11: Non | AA11: Infirmerie Couloir Assistante sociale | AB11: Données médicales à l'infirmerie dans un classeur fermé à clé pour cetraines données Armoire du couloir fermée à clé Dans un placard du bureau des assistantes sociales fermé à clé | AC11: Mediateam | AD11: Accès restreint | AE11: Editeur | AF11: Mediateam | AG11: Oui | AH11: Mediateam | AI11: Interne :Directrice et chefs de service, professionnels, infirmière | AJ11: SO | AK11: Non | AL11: SO | AN11: 2 | AO11: 0 | AP11: =$AN11*AO11 -> 0 | AQ11: 0 | AR11: =$AN11*AQ11 -> 0 | AS11: 0 | AT11: =$AN11*AS11 -> 0 | AU11: 0 | AV11: =$AN11*AU11 -> 0 | AW11: 0 | AX11: =$AN11*AW11 -> 0 | AY11: 0 | AZ11: =$AN11*AY11 -> 0 | BA11: 0 | BB11: =$AN11*BA11 -> 0 | BC11: 0 | BD11: =$AN11*BC11 -> 0 | BE11: 0 | BF11: =$AN11*BE11 -> 0 | BG11: 0 | BH11: =$AN11*BG11 -> 0 | BI11: =AP11:AP11+AR11:AR11+AT11:AT11+AV11:AV11+AX11:AX11+AZ11:AZ11+BB11:BB11+BD11:BD11+BF11:BF11+BH11:BH11 -> 0 | BJ11: Se référer au document word de préconisation | BK11: 1 | BO11: X | BR11: X
B12: 6 | C12: DIME Rennes | D12: Usagers Familles et proches des usagers | E12: Admission | F12: 44277 | G12: 45855 | H12: Ajout durée d'archivage | I12: Groupe CREATIVE | J12: Directeur de l'organisme | K12: Chefs de service et directeurs | L12: Collecter les informations personnelles permettant d’enregistrer administrativement le nouvel usager | M12: - Gestion de l'admission - Etat des présences - Réalisation d'états statistiques ou de listes pour répondre à des besoins de gestion administrative - Gestion des élections des représentants CVS - Gestion des enquêtes (ANAP - EHPA...) - Rapport d'activité - Gestion des mutuelles - Gestion des contacts en cas d'urgence et de la personne de confiance - Gestion décès - Gestion de la facturation des usagers - Gestion du courrier - Gestion du linge - Gestion des repas - Gestion du droit à l'image | N12: Usagers Familles et proches des usagers | O12: Nom d’usage Nom de naissance Prénom(s) Date de naissance, lieu, ancienne adresse N° Sécurité sociale N° CAF/MSA, adresse, téléphone, noms, prénoms, coordonnées téléphoniques et adresses email des intervenants nom et les coordonnées téléphoniques de la personne à contacter en cas d’urgence | R12: - Situation familiale - Livret de famille - Lieu de résidence lors de l’enfance - Nombre de frères et sœurs - Origine et profession des parents - Provenance - Mesure de protection juridique - Goûts et loisirs | S12: - aides financieres - demande de prélevement | U12: Carte d’invalidite Copie de l’attestation de Sécurité sociale Copie de l’extrait de jugement s’il existe une mesure de protection juridique Copie de la dernière ordonnance antécédents, carnet de vaccination Bilan de santé | V12: NIR (N° SS) Donnée de santé | W12: Données sensibles (Art 9) ou données relatives aux condamnations pénales ou aux infractions (Art 10) | X12: usager / famille / proches des usagers / organisme de protection juridique | Y12: Fondé sur l’exécution d’un contrat avec la personne physique concernée, | Z12: Non | AA12: Infirmerie IME Bureau du pédopsychiatre | AB12: Classeur des entretiens avec les familles et Dossier médical papier dans une armoire de l'infirmerie IME Affichage de liste des jeunes et de prise en charge thérapeutiques dans l'infirmerie IME Tiroir fermé à clé dans le Bureau du pédopsychiatre | AC12: Serveur Mediateam Viatrajectoire ROR Qualinéo RésidESMS ATIH Enquête éducation nationale 32 Enquêtes ARS | AD12: Sauvegarde sur le serveur dans un répertoire service avec accès restreint User/mdp | AE12: Interne (AJP) Berger Levrault …. | AF12: SO | AG12: Oui | AH12: 20 ans après le départ de l'usager | AI12: Interne : Infirmière IME, secrétaire de direction IME, pédopsychiatre, Assistante sociale Externe : ARS | AJ12: SO | AK12: Non | AL12: SO | AN12: 2 | AO12: 0 | AP12: =$AN12*AO12 -> 0 | AQ12: 0 | AR12: =$AN12*AQ12 -> 0 | AS12: 3 | AT12: =$AN12*AS12 -> 6 | AU12: 1 | AV12: =$AN12*AU12 -> 2 | AW12: 2 | AX12: =$AN12*AW12 -> 4 | AY12: 0 | AZ12: =$AN12*AY12 -> 0 | BA12: 0 | BB12: =$AN12*BA12 -> 0 | BC12: 0 | BD12: =$AN12*BC12 -> 0 | BE12: 0 | BF12: =$AN12*BE12 -> 0 | BG12: 0 | BH12: =$AN12*BG12 -> 0 | BI12: =AP12:AP12+AR12:AR12+AT12:AT12+AV12:AV12+AX12:AX12+AZ12:AZ12+BB12:BB12+BD12:BD12+BF12:BF12+BH12:BH12 -> 12 | BJ12: Se référer au document word de préconisation | BK12: 1 | BO12: X | BR12: X
B13: 7 | C13: ESAT LA Simonière | D13: Usagers Familles et proches des usagers | E13: Admission | F13: 44277 | G13: 45562 | H13: Modif des durées d'archivage | I13: Groupe CREATIVE | J13: Directeur de l'organisme | K13: Chefs de service et directeurs | L13: Collecter les informations personnelles permettant d’enregistrer administrativement le nouvel usager | M13: - Gestion de l'admission - Etat des présences - Réalisation d'états statistiques ou de listes pour répondre à des besoins de gestion administrative - Gestion des élections des représentants CVS - Gestion des enquêtes (ANAP - EHPA...) - Rapport d'activité - Gestion des mutuelles - Gestion des contacts en cas d'urgence et de la personne de confiance - Gestion décès - Gestion du linge pro - Gestion du droit à l'image | N13: Travailleurs | O13: Nom d’usage Nom de naissance Prénom(s) Date de naissance, lieu, N° Sécurité sociale N° CAF/MSA, adresse, téléphone, email photographie nom de la mutuelle nom et les coordonnées téléphoniques de la personne à contacter en cas d’urgence, personne de confiance attestation de responsabilité civile, permis de conduire, médecin traitant et spécialiste, photocopie de la CI | R13: Situation familiale Nombre d’enfant(s) Etablissement d'origine, présence d’un aidant, prestation en place (SSIAD, ADMR…) Mesure de protection juridique Droit à l'image | S13: RIB | T13: Niveau scolaire, expérience professionnelle (CV) | U13: Point de vigilance santé / Comportement Carte vitale Mesure de protection judiciaire et RQTH carte d'invalidité | V13: NIR (N° SS) Donnée de santé | W13: Données sensibles (Art 9) ou données relatives aux condamnations pénales ou aux infractions (Art 10) | X13: usager / famille / proches des usagers / organisme de protection juridique | Y13: Fondé sur l’exécution d’un contrat avec la personne physique concernée, | Z13: Non | AA13: Bureau de l'assistante administrative | AB13: Armoire fermée à clé dans le bureau de l'assistante administrative fermé à clé | AC13: Serveur de fichier Mediateam | AD13: User + Mdp | AE13: Interne Berger Levrault | AF13: O | AG13: OUI | AH13: Pas de suppression | AI13: Interne : Assistante administrative, chef de service, chargé d'accompagnement, moniteur, directrice, psychologue Externe : MSA, médecine du travail, mutuelle, MDPH, CAF, Viatrajectoire, ARS | AJ13: Mutuelle des usagers | AK13: Non | AL13: SO | AM13: Archivage dans le grenier au dessus des vestiaires 03/06/25 : Pas de nettoyage encore, pas encore planifié, beaucoup d'installation de logiciel cette année | AN13: 2 | AO13: 0 | AP13: =$AN13*AO13 -> 0 | AQ13: 0 | AR13: =$AN13*AQ13 -> 0 | AS13: 2 | AT13: =$AN13*AS13 -> 4 | AU13: 0 | AV13: =$AN13*AU13 -> 0 | AW13: 0 | AX13: =$AN13*AW13 -> 0 | AY13: 0 | AZ13: =$AN13*AY13 -> 0 | BA13: 0 | BB13: =$AN13*BA13 -> 0 | BC13: 0 | BD13: =$AN13*BC13 -> 0 | BE13: 0 | BF13: =$AN13*BE13 -> 0 | BG13: 0 | BH13: =$AN13*BG13 -> 0 | BI13: =AP13:AP13+AR13:AR13+AT13:AT13+AV13:AV13+AX13:AX13+AZ13:AZ13+BB13:BB13+BD13:BD13+BF13:BF13+BH13:BH13 -> 4 | BK13: 1 | BO13: X | BR13: X
B14: 8 | C14: ESAT Les espoirs | D14: Usagers Familles et proches des usagers | E14: Admission | F14: 45078 | I14: Groupe CREATIVE | J14: Directeur de l'organisme | K14: Chefs de service et directeurs | L14: Collecter les informations personnelles permettant d’enregistrer administrativement le nouvel usager | M14: - Gestion de l'admission - Etat des présences - Réalisation d'états statistiques ou de listes pour répondre à des besoins de gestion administrative - Gestion des élections des représentants CVS - Gestion des enquêtes (ANAP - EHPA...) - Rapport d'activité - Gestion des mutuelles - Gestion des contacts en cas d'urgence et de la personne de confiance - Gestion décès - Gestion du linge pro - Gestion du droit à l'image | N14: Travailleurs | O14: Nom d’usage Nom de naissance Prénom(s) Date de naissance, lieu, N° Sécurité sociale N° CAF/MSA, adresse, téléphone, email photographie nom et les coordonnées téléphoniques de la personne à contacter en cas d’urgence, et de la personne de confiance | R14: Situation familiale Nombre d’enfant(s), frère(s) et sœur(s) Origine et profession des parents Etablissement d'origine, Mesure de protection juridique Droit à l'image | S14: - aides financières - demande de prélèvement + RIB | T14: Profession exercée profession du conjoint | U14: Carte d’invalidité copie de l’attestation de Sécurité sociale copie de l’extrait de jugement s’il existe une mesure de protection juridique copie de la dernière ordonnance | V14: NIR (N° SS) Donnée de santé | W14: Données sensibles (Art 9) ou données relatives aux condamnations pénales ou aux infractions (Art 10) | X14: usager / famille / proches des usagers / organisme de protection juridique | Y14: Fondé sur l’exécution d’un contrat avec la personne physique concernée, | Z14: Non | AA14: Bureau de la secrétaire de direction Bureau du Chef du service social Bureau du service d'accompagnement | AB14: Dans une armoire fermée à clé de bureau fermé à clé | AC14: Mediateam | AD14: User + Mdp | AE14: Berger Levrault | AF14: Mediateam | AG14: Oui | AH14: Mediateam | AI14: Interne : Secrétaire de direction, directeur, Chef de service social, Chargé d'accompagnement, Psychologue | AJ14: SO | AK14: Non | AL14: SO | AM14: ESAT Les espoirs : Avec l'utilisation massive de Meaditeam en 2025, possible svg en local de chaque dossier | AN14: 2 | AO14: 0 | AP14: =$AN14*AO14 -> 0 | AQ14: 0 | AR14: =$AN14*AQ14 -> 0 | AS14: 0 | AT14: =$AN14*AS14 -> 0 | AU14: 0 | AV14: =$AN14*AU14 -> 0 | AW14: 2 | AX14: =$AN14*AW14 -> 4 | AY14: 0 | AZ14: =$AN14*AY14 -> 0 | BA14: 0 | BB14: =$AN14*BA14 -> 0 | BC14: 0 | BD14: =$AN14*BC14 -> 0 | BE14: 0 | BF14: =$AN14*BE14 -> 0 | BG14: 0 | BH14: =$AN14*BG14 -> 0 | BI14: =AP14:AP14+AR14:AR14+AT14:AT14+AV14:AV14+AX14:AX14+AZ14:AZ14+BB14:BB14+BD14:BD14+BF14:BF14+BH14:BH14 -> 4 | BK14: 1 | BO14: X | BR14: X
B15: 9 | C15: SAVS Tinténiac | D15: Usagers Familles et proches des usagers | E15: Admission | F15: 45090 | G15: 02/09/2024 28/07/2025 | H15: Modif données sensibles colectées Modif données sensibles collectées - 28/07/25 | I15: Groupe CREATIVE | J15: Directeur de l'organisme | K15: Secrétaire | L15: Collecter les informations personnelles permettant d’enregistrer administrativement le nouvel usager | M15: - Gestion du dossier du bénéficiaire - Gestion de l'admission - Etat des présences - Réalisation d'états statistiques ou de listes pour répondre à des besoins de gestion administrative - Gestion des enquêtes (ANAP - EHPA...) - Rapport d'activité - Gestion des contacts en cas d'urgence - Gestion décès - Gestion du courrier - Gestion du droit à l'IMAGE | N15: Usagers Familles et proches des usagers | O15: Nom d’usage Nom de naissance Prénom(s) Date de naissance, lieu, ancienne adresse N° Sécurité sociale, adresse, téléphone, photographie noms, prénoms, coordonnées téléphoniques et adresses email des intervenants nom et les coordonnées téléphoniques de la personne à contacter en cas d’urgence | U15: Notification MDPH une mesure de protection juridique | V15: NIR (N° SS) | W15: Données sensibles (Art 9) ou données relatives aux condamnations pénales ou aux infractions (Art 10) | X15: usager / famille / proches des usagers / organisme de protection juridique | Y15: Fondé sur l’exécution d’un contrat avec la personne physique concernée, | Z15: Non | AA15: SO | AB15: SO | AC15: Mediateam | AD15: User/mdp | AE15: Berger Levrault | AF15: Mediateam | AG15: Oui | AH15: Mediateam | AI15: Interne : Tout le personnel Externe : MDPH & ViaTrajectoire | AJ15: SO | AK15: Non | AL15: SO | AN15: 2 | AO15: 0 | AP15: =$AN15*AO15 -> 0 | AQ15: 0 | AR15: =$AN15*AQ15 -> 0 | AS15: 0 | AT15: =$AN15*AS15 -> 0 | AU15: 0 | AV15: =$AN15*AU15 -> 0 | AW15: 0 | AX15: =$AN15*AW15 -> 0 | AY15: 0 | AZ15: =$AN15*AY15 -> 0 | BA15: 0 | BB15: =$AN15*BA15 -> 0 | BC15: 0 | BD15: =$AN15*BC15 -> 0 | BE15: 0 | BF15: =$AN15*BE15 -> 0 | BG15: 0 | BH15: =$AN15*BG15 -> 0 | BI15: =AP15:AP15+AR15:AR15+AT15:AT15+AV15:AV15+AX15:AX15+AZ15:AZ15+BB15:BB15+BD15:BD15+BF15:BF15+BH15:BH15 -> 0 | BK15: 1 | BO15: X | BR15: X
B16: 10 | C16: SAVA Itinéraire Bis | D16: Usagers Familles et proches des usagers | E16: Admission | F16: 45090 | G16: 45090 | H16: Modification de la partie stockage physique Ajout de précision sur la partie papier (15/07/25) | I16: Groupe CREATIVE | J16: Directeur de l'organisme | K16: Chefs de service et directeurs | L16: Collecter les informations personnelles permettant d’enregistrer administrativement le nouvel usager | M16: - Gestion du dossier du bénéficiaire - Gestion de l'admission - Etat des présences - Réalisation d'états statistiques ou de listes pour répondre à des besoins de gestion administrative - Gestion des enquêtes (ANAP - EHPA...) - Rapport d'activité - Gestion des contacts en cas d'urgence - Gestion décès - Gestion du courrier - Gestion du droit à l'IMAGE | N16: Usagers Familles et proches des usagers | O16: Nom d’usage Nom de naissance Prénom(s) Date de naissance, lieu, ancienne adresse N° Sécurité sociale N° CAF/MSA, adresse, téléphone, photographie noms, prénoms, coordonnées téléphoniques et adresses email des intervenants nom et les coordonnées téléphoniques de la personne à contacter en cas d’urgence (si existe), Assurance, mutuelle, copie carte d'iden-tité, permis de conduire (si donné), justificatif de domicile | R16: - Situation familiale - Nombre d’enfant(s) - Nombre de petits enfants - Lieu de résidence lors de l’enfance - Nombre de frères et sœurs - Provenance - Mesure de protection juridique - Goûts et loisirs | S16: - aides financieres - demande de prélevement + RIB | T16: Profession exercée profession du conjoint | U16: Carte d’invalidite copie de l’attestation de Sécurité sociale copie de l’extrait de jugement s’il existe une mesure de protection juridique copie de la dernière ordonnance antécédents Bilan professionnel de l'ancienne structure | V16: NIR (N° SS) Donnée de santé | W16: Données sensibles (Art 9) ou données relatives aux condamnations pénales ou aux infractions (Art 10) | X16: usager / famille / proches des usagers / organisme de protection juridique | Y16: Fondé sur l’exécution d’un contrat avec la personne physique concernée, | Z16: Non | AA16: Bureau des éducateurs | AB16: Quelques dossiers papier reçu ou imprimé dans le caisson des éducateurs, fermé à clé De moins en moins de dossier papier (informations temporaires avant numérisation) | AC16: Mediateam - serveur | AD16: User/mdp | AE16: Berger Levrault | AF16: Mediateam | AG16: Oui | AH16: Mediateam | AI16: Interne : Tout le personnel Externe : | AJ16: SO | AK16: Non | AL16: SO | AN16: 2 | AO16: 0 | AP16: =$AN16*AO16 -> 0 | AQ16: 0 | AR16: =$AN16*AQ16 -> 0 | AS16: 0 | AT16: =$AN16*AS16 -> 0 | AU16: 0 | AV16: =$AN16*AU16 -> 0 | AW16: 0 | AX16: =$AN16*AW16 -> 0 | AY16: 0 | AZ16: =$AN16*AY16 -> 0 | BA16: 0 | BB16: =$AN16*BA16 -> 0 | BC16: 0 | BD16: =$AN16*BC16 -> 0 | BE16: 0 | BF16: =$AN16*BE16 -> 0 | BG16: 0 | BH16: =$AN16*BG16 -> 0 | BI16: =AP16:AP16+AR16:AR16+AT16:AT16+AV16:AV16+AX16:AX16+AZ16:AZ16+BB16:BB16+BD16:BD16+BF16:BF16+BH16:BH16 -> 0 | BK16: 1 | BO16: X | BR16: X
B17: 11 | C17: Résidence La Combe | D17: Usagers Familles et proches des usagers | E17: Admission | F17: 45076 | G17: 45561 | H17: Données papier seulement à l'infirmerie, plus dans le couloir | I17: Groupe CREATIVE | J17: Directeur de l'organisme | K17: Chefs de service et directeurs | L17: Collecter les informations personnelles permettant d’enregistrer administrativement le nouvel usager | M17: - Gestion de l'admission - Etat des présences - Réalisation d'états statistiques ou de listes pour répondre à des besoins de gestion administrative - Gestion des élections des représentants CVS - Gestion des enquêtes (ANAP - EHPA...) - Rapport d'activité - Gestion des mutuelles - Gestion des contacts en cas d'urgence et de la personne de confiance - Gestion décès - Gestion de la facturation des usagers - Gestion du courrier - Gestion du linge - Gestion des repas - Gestion du droit à l'image | N17: Usagers Familles et proches des usagers | O17: Nom d’usage Nom de naissance Prénom(s) Date de naissance, lieu, ancienne adresse N° Sécurité sociale N° CAF/MSA, adresse, téléphone, photographie noms, prénoms, coordonnées téléphoniques et adresses email des intervenants nom et les coordonnées téléphoniques de la personne à contacter en cas d’urgence | R17: - Situation familiale - Nombre d’enfant(s) - Lieu de résidence lors de l’enfance - Nombre de frères et sœurs - Origine et profession des parents - Provenance - Mesure de protection juridique - Goûts et loisirs | S17: - aides financieres - demande de prélevement + RIB | T17: Profession des parents, expérience professionnelle | U17: Carte d’invalidite copie de l’attestation de Sécurité sociale copie de l’extrait de jugement s’il existe une mesure de protection juridique copie de la dernière ordonnance antécédents | V17: NIR (N° SS) Donnée de santé | W17: Données sensibles (Art 9) ou données relatives aux condamnations pénales ou aux infractions (Art 10) | X17: usager / famille / proches des usagers / organisme de protection juridique | Y17: Fondé sur l’exécution d’un contrat avec la personne physique concernée, | Z17: Non | AA17: Infirmerie | AB17: Données médicales à l'infirmerie dans un classeur fermé à clé pour les données médicales | AC17: Mediateam | AD17: Accès restreint | AE17: Berger Levrault | AF17: Mediateam | AG17: Oui | AH17: Mediateam | AI17: Interne :Directrice et chefs de service, professionnels, infirmière | AJ17: SO | AK17: Non | AL17: SO | AN17: 2 | AO17: 0 | AP17: =$AN17*AO17 -> 0 | AQ17: 0 | AR17: =$AN17*AQ17 -> 0 | AS17: 0 | AT17: =$AN17*AS17 -> 0 | AU17: 0 | AV17: =$AN17*AU17 -> 0 | AW17: 0 | AX17: =$AN17*AW17 -> 0 | AY17: 0 | AZ17: =$AN17*AY17 -> 0 | BA17: 0 | BB17: =$AN17*BA17 -> 0 | BC17: 0 | BD17: =$AN17*BC17 -> 0 | BE17: 0 | BF17: =$AN17*BE17 -> 0 | BG17: 0 | BH17: =$AN17*BG17 -> 0 | BI17: =AP17:AP17+AR17:AR17+AT17:AT17+AV17:AV17+AX17:AX17+AZ17:AZ17+BB17:BB17+BD17:BD17+BF17:BF17+BH17:BH17 -> 0 | BK17: 1 | BO17: X | BR17: X
B18: 12 | C18: Résidence du parc des bois | D18: Usagers Familles et proches des usagers | E18: Admission | F18: 45076 | G18: 45468 | H18: Modification des données collectées et de leur empacement | I18: Groupe CREATIVE | J18: Directeur de l'organisme | K18: Chefs de service et directeurs | L18: Collecter les informations personnelles permettant d’enregistrer administrativement le nouvel usager | M18: - Gestion de l'admission - Etat des présences - Réalisation d'états statistiques ou de listes pour répondre à des besoins de gestion administrative - Gestion des élections des représentants CVS - Gestion des enquêtes (ANAP - EHPA...) - Rapport d'activité - Gestion des mutuelles - Gestion des contacts en cas d'urgence et de la personne de confiance - Gestion décès - Gestion de la facturation des usagers - Gestion du courrier - Gestion du linge - Gestion des repas - Gestion du droit à l'image | N18: Usagers Familles et proches des usagers | O18: Nom d’usage Nom de naissance Prénom(s) Date de naissance, lieu, ancienne adresse N° Sécurité sociale N° CAF/MSA, adresse, téléphone, photographie noms, prénoms, coordonnées téléphoniques et adresses email des intervenants nom et les coordonnées téléphoniques de la personne à contacter en cas d’urgence | R18: - Situation familiale - Nombre d’enfant(s) - Nombre de frères et sœurs - Mesure de protection juridique - Goûts et loisirs - Notification de décision (du Dpt) | S18: - aides financieres pour la comptable - demande de prélevement + RIB pour la comptable | T18: Profession des parents, expérience professionnelle du jeune | U18: Carte d’invalidite copie de l’attestation de Sécurité sociale, mutuelle, pièce d'identité (carte de séjour et extrait de l'acte de naissance) copie de l’extrait de jugement s’il existe une mesure de protection juridique copie de la dernière ordonnance antécédents Orientation MDPH | V18: NIR (N° SS) Donnée de santé | W18: Données sensibles (Art 9) ou données relatives aux condamnations pénales ou aux infractions (Art 10) | X18: usager / famille / proches des usagers / organisme de protection juridique | Y18: Fondé sur l’exécution d’un contrat avec la personne physique concernée, | Z18: Non | AA18: Pharmacie | AB18: Accès sécurisé à la pharmacie pour les données médicales | AC18: Mediateam PC de l'infirmière | AD18: Accès restreint par utilisateur accès spécifique de l'infirmière | AE18: Berger Levrault | AF18: Mediateam | AG18: Oui | AH18: Mediateam | AI18: Interne :Directrice et chefs de service, professionnels, infirmière | AJ18: SO | AK18: Non | AL18: SO | AO18: 0 | AP18: =$AN18*AO18 -> 0 | AQ18: 0 | AS18: 0 | AU18: 0 | AW18: 0 | AY18: 0 | BA18: 0 | BC18: 0 | BG18: 0 | BK18: 1 | BO18: X | BR18: X
B19: 13 | C19: Résidences Les Gantelles et Les Fougères | D19: Usagers Familles et proches des usagers | E19: Admission | F19: 45582 | G19: 45838 | H19: Ajout d'un commentaire | I19: Groupe CREATIVE | J19: Directeur de l'organisme | K19: Cheffe de service | L19: Collecter les informations personnelles permettant d’enregistrer administrativement le nouvel usager | M19: - Gestion de l'admission - Etat des présences - Réalisation d'états statistiques ou de listes pour répondre à des besoins de gestion administrative - Gestion des élections des représentants CVS - Gestion des enquêtes (ANAP - EHPA...) - Rapport d'activité - Gestion des mutuelles - Gestion des contacts en cas d'urgence et de la personne de confiance - Gestion décès - Gestion de la facturation des usagers - Gestion du courrier - Gestion du linge - Gestion des repas - Gestion du droit à l'image | N19: Usagers Familles et proches des usagers | O19: Nom d’usage Nom de naissance Prénom(s) Date de naissance, lieu, ancienne adresse N° Sécurité sociale N° CAF/MSA, adresse, téléphone, photographie noms, prénoms, coordonnées téléphoniques et adresses email des intervenants nom et les coordonnées téléphoniques de la personne à contacter en cas d’urgence | R19: - Situation familiale - Nombre d’enfant(s) - Nombre de frères et sœurs - Mesure de protection juridique - Goûts et loisirs - Notification de décision (du Dpt) | S19: - aides financieres pour la comptable - demande de prélevement + RIB pour la comptable | T19: Profession des parents, expérience professionnelle du jeune | U19: Carte d’invalidite copie de l’attestation de Sécurité sociale, mutuelle, pièce d'identité (carte de séjour et extrait de l'acte de naissance) copie de l’extrait de jugement s’il existe une mesure de protection juridique copie de la dernière ordonnance antécédents Orientation MDPH | V19: NIR (N° SS) Donnée de santé | W19: Données sensibles (Art 9) ou données relatives aux condamnations pénales ou aux infractions (Art 10) | X19: usager / famille / proches des usagers / organisme de protection juridique | Y19: Fondé sur l’exécution d’un contrat avec la personne physique concernée, | Z19: Non | AA19: Bureau de la direction | AB19: Armoire fermée à clé contenant les dossiers des résidents des 2 foyers dans le bureau de la direction fermé à clé | AC19: SO | AD19: SO | AE19: SO | AF19: Non définie | AG19: Oui | AH19: Non définie | AI19: Interne : Cheffe de service, professionnels | AJ19: SO | AK19: Non | AL19: SO | AM19: Actuellement les résidents gèrent les points suivants en attendant que cela reviennent aux foyers : - Gestion des mutuelles - Gestion du courrier - Gestion du linge - Gestion des repas | AN19: 2 | AO19: 0 | AP19: =$AN19*AO19 -> 0 | AQ19: 0 | AR19: =$AN19*AQ19 -> 0 | AS19: 0 | AT19: =$AN19*AS19 -> 0 | AU19: 0 | AV19: =$AN19*AU19 -> 0 | AW19: 2 | AX19: =$AN19*AW19 -> 4 | AY19: 0 | AZ19: =$AN19*AY19 -> 0 | BA19: 0 | BB19: =$AN19*BA19 -> 0 | BC19: 0 | BD19: =$AN19*BC19 -> 0 | BE19: 0 | BF19: =$AN19*BE19 -> 0 | BG19: 0 | BH19: =$AN19*BG19 -> 0 | BI19: =AP19:AP19+AR19:AR19+AT19:AT19+AV19:AV19+AX19:AX19+AZ19:AZ19+BB19:BB19+BD19:BD19+BF19:BF19+BH19:BH19 -> 4 | BK19: 1 | BO19: X | BR19: X
B20: 14 | C20: DIME Rennes | D20: Usagers Familles et proches des usagers | E20: Accompagnement des usagers - Partie non médicale | F20: 44277 | G20: 45855 | H20: Modification des données collectées et de leur empacement | I20: Groupe CREATIVE | J20: Directeur de l'organisme | K20: Chef de service | L20: Collecter et utiliser des données permettant de construire le projet d’accompagnement personnalisé des usagers et d’organiser et tracer l'accompagnement à apporter | M20: - Elaboration des projets d'accompagnement personnalisés - Gestion des prestations non médicales - Préparation des repas adaptés aux besoins de l'usager | N20: Usagers Familles et proches des usagers | O20: Nom d’usage Nom de naissance Prénom(s) | R20: situation familiale informations sur sa vie (généalogie, habitude, parcours, habitudes, plaisirs, hygiène, vêtements, toilette, ...) motricité et deplacement prothèses, caractéristiques sensorielles | U20: Copie MDPH, Copie des pièces d'identité, de jugement, Info sur les échanges avec partenaires, Projet personnalisé des jeunes, NIR | V20: Concernant la santé | W20: Données sensibles (Art 9) ou données relatives aux condamnations pénales ou aux infractions (Art 10) | X20: usager / famille / proches des usagers / organisme de protection juridique | Y20: Fondé sur le consentement préalable de la personne physique, | Z20: Non | AA20: Infirmerie IME Bureau du pédopsychiatre Salle de communication IME | AB20: Classeur des entretiens avec les familles et Dossier médical papier dans une armoire de l'infirmerie IME Affichage de liste des jeunes et de prise en charge thérapeutiques dans l'infirmerie IME Tiroir fermé à clé dans le Bureau du pédopsychiatre Version dans les dossiers papier administratifs dans la salle de communication fermé à clé | AC20: Mediateam | AD20: Accès restreint par utilisateur | AE20: Berger Levrault | AF20: Mediateam | AG20: Oui | AH20: Mediateam | AI20: Interne :Directrice et chefs de service, professionnels, infirmière | AJ20: SO | AK20: Non | AL20: SO | AM20: Encore gestion papier en attendant la gestion des droits sur Mediateam | AN20: 1 | AO20: 0 | AP20: =$AN20*AO20 -> 0 | AQ20: 0 | AR20: =$AN20*AQ20 -> 0 | AS20: 0 | AT20: =$AN20*AS20 -> 0 | AU20: 0 | AV20: =$AN20*AU20 -> 0 | AW20: 2 | AX20: =$AN20*AW20 -> 2 | AY20: 0 | AZ20: =$AN20*AY20 -> 0 | BA20: 0 | BB20: =$AN20*BA20 -> 0 | BC20: 0 | BD20: =$AN20*BC20 -> 0 | BE20: 0 | BF20: =$AN20*BE20 -> 0 | BG20: 0 | BH20: =$AN20*BG20 -> 0 | BI20: =AP20:AP20+AR20:AR20+AT20:AT20+AV20:AV20+AX20:AX20+AZ20:AZ20+BB20:BB20+BD20:BD20+BF20:BF20+BH20:BH20 -> 2 | BJ20: Se référer au document word de préconisation | BK20: 1 | BO20: X | BR20: X
B21: 15 | C21: DIME La Bretèche | D21: Usagers Familles et proches des usagers | E21: Accompagnement des usagers - Partie non médicale | F21: 44277 | G21: 45527 | H21: Pas de donnée de santé | I21: Groupe CREATIVE | J21: Directeur de l'organisme | K21: Chef de service | L21: Collecter et utiliser des données permettant de construire le projet d’accompagnement personnalisé des usagers et d’organiser et tracer l'accompagnement à apporter | M21: - Elaboration des projets d'accompagnement personnalisés - Gestion des prestations non médicales - Préparation des repas adaptés aux besoins de l'usager | N21: Usagers Familles et proches des usagers | O21: Nom d’usage Nom de naissance Prénom(s) | R21: Dernier lieu de provenance (établissement d'origine, GEVASCO, PPA) Situation familiale informations sur sa vie (généalogie, habitude, parcours, plaisirs, hygiène, vêtements, toilette, ...) motricité, caractéristiques sensorielles | V21: Concernant la santé | W21: Données sensibles (Art 9) ou données relatives aux condamnations pénales ou aux infractions (Art 10) | X21: usager / famille / proches des usagers | Y21: Fondé sur le consentement préalable de la personne physique, | Z21: Non | AA21: Couloir près de la directrice | AB21: Armoire fermée à clé | AC21: Mediateam | AD21: Accès restreint par utilisateur | AE21: Berger Levrault | AF21: Mediateam | AG21: Oui | AH21: Mediateam | AI21: Interne : tous les professionnels Externe ::Partenaire (Stage) | AJ21: Présentation du jeune et de son dossier pour un stage auprès du partenaire | AK21: Non | AL21: SO | AN21: 1 | AO21: 0 | AP21: =$AN21*AO21 -> 0 | AQ21: 0 | AR21: =$AN21*AQ21 -> 0 | AS21: 0 | AT21: =$AN21*AS21 -> 0 | AU21: 0 | AV21: =$AN21*AU21 -> 0 | AW21: 0 | AX21: =$AN21*AW21 -> 0 | AY21: 0 | AZ21: =$AN21*AY21 -> 0 | BA21: 0 | BB21: =$AN21*BA21 -> 0 | BC21: 1 | BD21: =$AN21*BC21 -> 1 | BE21: 0 | BF21: =$AN21*BE21 -> 0 | BG21: 0 | BH21: =$AN21*BG21 -> 0 | BI21: =AP21:AP21+AR21:AR21+AT21:AT21+AV21:AV21+AX21:AX21+AZ21:AZ21+BB21:BB21+BD21:BD21+BF21:BF21+BH21:BH21 -> 1 | BJ21: Se référer au document word de préconisation | BK21: 1 | BO21: X | BR21: X
B22: 16 | C22: ESAT LA Simonière | D22: Usagers Familles et proches des usagers | E22: Accompagnement des usagers - Partie non médicale | F22: 44277 | G22: 45562 | H22: Modif des durées d'archivage et des données collectées | I22: Groupe CREATIVE | J22: Directeur de l'organisme | K22: Chef de service | L22: Collecter et utiliser des données permettant de construire le projet d’accompagnement personnalisé des usagers et d’organiser et tracer l'accompagnement à apporter | M22: - Elaboration des projets d'accompagnement personnalisés - Paiement des usagers (rémunération garantie) | N22: Usagers | O22: Nom d’usage Nom de naissance Prénom(s) Date de naissance, lieu, N° Sécurité sociale N° CAF/MSA, adresse, téléphone, email photographie nom de la mutuelle nom et les coordonnées téléphoniques de la personne à contacter en cas d’urgence, personne de confiance attestation de responsabilité civile, permis de conduire, médecin traitant et spécialiste, photocopie de la CI, suivi des heures, convention de stage | R22: Situation familiale Nombre d’enfant(s) Etablissement d'origine, présence d’un aidant, prestation en place (SSIAD, ADMR…) Mesure de protection juridique Droit à l'image | T22: Niveau scolaire, expérience professionnelle (CV) Projet personnalisé, contrat de soutien et d'aide par le travail, formations réalisées, DIPC | U22: Point de vigilance santé / Comportement Carte vitale Mesure de protection judiciaire et RQTH carte d'invalidité Titre de séjour + validité | V22: Concernant la santé | W22: Données sensibles (Art 9) ou données relatives aux condamnations pénales ou aux infractions (Art 10) | X22: Usagers / famille / proches des usagers | Y22: Fondé sur le consentement préalable de la personne physique, | Z22: Non | AA22: Bureau de l'assistante administrative Bureau de la chef de service | AB22: Armoire fermée à clé dans le bureau de l'assistante administrative fermé à clé Copie du PAP dans une armoire du bureau de la chef de service fermé à clé | AC22: serveur & Mediateam & Mail | AD22: Compte rendu d'acc sur le serveur & Médiateam & Mail (sécurisé par User & MDP) | AE22: Interne Berger Levrault | AF22: O | AG22: OUI | AH22: Pas de suppression | AI22: Interne : chef de service, psychologue, moniteurs, animatrice, chargé d'accompagnement social, MPA, directrice, assistante administrative Service RH (formation) et service Paie au siège Externe : OPCO | AJ22: SO | AK22: Non | AL22: SO | AN22: 1 | AO22: 0 | AP22: =$AN22*AO22 -> 0 | AQ22: 0 | AR22: =$AN22*AQ22 -> 0 | AS22: 3 | AT22: =$AN22*AS22 -> 3 | AU22: 0 | AV22: =$AN22*AU22 -> 0 | AW22: 0 | AX22: =$AN22*AW22 -> 0 | AY22: 0 | AZ22: =$AN22*AY22 -> 0 | BA22: 0 | BB22: =$AN22*BA22 -> 0 | BC22: 0 | BD22: =$AN22*BC22 -> 0 | BE22: 0 | BF22: =$AN22*BE22 -> 0 | BG22: 0 | BH22: =$AN22*BG22 -> 0 | BI22: =AP22:AP22+AR22:AR22+AT22:AT22+AV22:AV22+AX22:AX22+AZ22:AZ22+BB22:BB22+BD22:BD22+BF22:BF22+BH22:BH22 -> 3 | BK22: 1 | BO22: X | BR22: X
B23: 17 | C23: ESAT Les espoirs | D23: Usagers Familles et proches des usagers | E23: Accompagnement des usagers - Partie non médicale | F23: 45078 | G23: 19/12/2024 19/08/2025 | H23: MAJ du comentaire MAJ du comentaire (19/08/25) | I23: Groupe CREATIVE | J23: Directeur de l'organisme | K23: Chef de service | L23: Collecter et utiliser des données permettant de construire le projet d’accompagnement personnalisé des usagers et d’organiser et tracer l'accompagnement à apporter | M23: - Elaboration des projets d'accompagnement personnalisés - Paiement des usagers (rémunération garantie) - Gestion des prestations non médicales - Préparation des repas adaptés aux besoins de l'usagers | N23: Usagers | O23: Nom d’usage Nom de naissance Prénom(s) Date d'entrée | R23: situation familiale informations sur sa vie (généalogie, habitude, parcours, habitudes, plaisirs, hygiène, vêtements, toilette, ...) motricité et déplacement prothèses, caractéristiques sensorielles nb d'enfants / d'enfants décédés | T23: Dernière profession | U23: Médecin traitant Contrainte alimentaires | V23: Concernant la santé | W23: Données sensibles (Art 9) ou données relatives aux condamnations pénales ou aux infractions (Art 10) | X23: Usagers / famille / proches des usagers | Y23: Fondé sur le consentement préalable de la personne physique, | Z23: Non | AA23: Bureau de la secrétaire de direction Bureau du Chef du service social Bureau du service d'accompagnement | AB23: Dans une armoire fermée à clé de bureau fermé à clé | AC23: Mediateam Dossier individuel sur le serveur (P:) | AD23: User + MDP Serveur de fichier accessible par tous les salariés | AE23: Interne Berger Levrault | AF23: Mediateam | AG23: Oui | AH23: Mediateam | AI23: Interne : chef de service, assistant social, psychologue, ES, animateur, CESF, moniteurs Externe : Tuteurs/curateurs | AJ23: SO | AK23: Non | AL23: SO | AM23: Prévoit un accompagnement par examen/certification pour aider les usagers à progresser (lecture, écriture, etc…) | AN23: 1 | AO23: 0 | AP23: =$AN23*AO23 -> 0 | AQ23: 0 | AR23: =$AN23*AQ23 -> 0 | AS23: 0 | AT23: =$AN23*AS23 -> 0 | AU23: 0 | AV23: =$AN23*AU23 -> 0 | AW23: 0 | AX23: =$AN23*AW23 -> 0 | AY23: 0 | AZ23: =$AN23*AY23 -> 0 | BA23: 0 | BB23: =$AN23*BA23 -> 0 | BC23: 1 | BD23: =$AN23*BC23 -> 1 | BE23: 0 | BF23: =$AN23*BE23 -> 0 | BG23: 0 | BH23: =$AN23*BG23 -> 0 | BI23: =AP23:AP23+AR23:AR23+AT23:AT23+AV23:AV23+AX23:AX23+AZ23:AZ23+BB23:BB23+BD23:BD23+BF23:BF23+BH23:BH23 -> 1 | BK23: 1 | BO23: X | BR23: X
B24: 18 | C24: SAVS Tinténiac | D24: Usagers Familles et proches des usagers | E24: Accompagnement des usagers - Partie non médicale | F24: 45090 | G24: 02/09/2024 28/07/2025 | H24: Modif du stockage numérique que sur Mediateam Modif données sensibles colectées 28/07/25 | I24: Groupe CREATIVE | J24: Directeur de l'organisme | K24: Chef de service | L24: Collecter et utiliser des données permettant de construire le projet d’accompagnement personnalisé des usagers et d’organiser et tracer l'accompagnement à apporter | M24: - Elaboration des projets d'accompagnement personnalisés - Gestion des prestations non médicales - Participation financière versée en fin d'année par les personnes accompagnées (30€) | N24: Usagers Familles et proches des usagers | O24: Nom d’usage Nom de naissance Prénom(s) | R24: Dernière profession situation familiale informations sur sa vie (généalogie, habitude, parcours...) motricité et déplacement, caractéristiques handicap nb d'enfants / d'enfants décédés | S24: - aides financières AH & PCH & APL& APA - Fiche d'impôt - demande de virement | T24: Parcours scolaire et professionnel | V24: Pas de donnée sensible | W24: Aucun cas retenu | X24: Usagers / famille / proches des usagers | Y24: Fondé sur le consentement préalable de la personne physique, | Z24: Non | AA24: SO | AB24: SO | AC24: Mediateam | AD24: Accès User + MDP | AE24: Berger Levrault | AF24: Durée de l'éditeur | AG24: Oui | AH24: Durée de l'éditeur | AI24: Interne : Salariés Externe : SO | AJ24: SO | AK24: Non | AL24: SO | AO24: 0 | AP24: =$AN24*AO24 -> 0 | AQ24: 0 | AR24: =$AN24*AQ24 -> 0 | AS24: 0 | AT24: =$AN24*AS24 -> 0 | AU24: 0 | AV24: =$AN24*AU24 -> 0 | AW24: 0 | AX24: =$AN24*AW24 -> 0 | AY24: 0 | AZ24: =$AN24*AY24 -> 0 | BA24: 0 | BB24: =$AN24*BA24 -> 0 | BC24: 0 | BD24: =$AN24*BC24 -> 0 | BE24: 0 | BF24: =$AN24*BE24 -> 0 | BG24: 0 | BH24: =$AN24*BG24 -> 0 | BI24: =AP24:AP24+AR24:AR24+AT24:AT24+AV24:AV24+AX24:AX24+AZ24:AZ24+BB24:BB24+BD24:BD24+BF24:BF24+BH24:BH24 -> 0 | BK24: 1 | BO24: X | BR24: X
